[2023-08-17 16:26:49,528] {taskinstance.py:1179} INFO - Dependencies all met for <TaskInstance: dag_etl.sensor_s3_obj scheduled__2023-05-16T00:00:00+00:00 [queued]>
[2023-08-17 16:26:49,622] {taskinstance.py:1179} INFO - Dependencies all met for <TaskInstance: dag_etl.sensor_s3_obj scheduled__2023-05-16T00:00:00+00:00 [queued]>
[2023-08-17 16:26:49,622] {taskinstance.py:1376} INFO - 
--------------------------------------------------------------------------------
[2023-08-17 16:26:49,623] {taskinstance.py:1377} INFO - Starting attempt 1 of 6
[2023-08-17 16:26:49,623] {taskinstance.py:1378} INFO - 
--------------------------------------------------------------------------------
[2023-08-17 16:26:49,943] {taskinstance.py:1397} INFO - Executing <Task(S3KeySensor): sensor_s3_obj> on 2023-05-16 00:00:00+00:00
[2023-08-17 16:26:50,009] {standard_task_runner.py:52} INFO - Started process 1309 to run task
[2023-08-17 16:26:50,106] {standard_task_runner.py:79} INFO - Running: ['***', 'tasks', 'run', 'dag_etl', 'sensor_s3_obj', 'scheduled__2023-05-16T00:00:00+00:00', '--job-id', '16', '--raw', '--subdir', 'DAGS_FOLDER/dag_etl_taskflow.py', '--cfg-path', '/tmp/tmpwbhle252', '--error-file', '/tmp/tmpimmgp4yr']
[2023-08-17 16:26:50,130] {standard_task_runner.py:80} INFO - Job 16: Subtask sensor_s3_obj
[2023-08-17 16:26:50,592] {task_command.py:371} INFO - Running <TaskInstance: dag_etl.sensor_s3_obj scheduled__2023-05-16T00:00:00+00:00 [running]> on host 1ea22a5e1d7f
[2023-08-17 16:26:51,191] {taskinstance.py:1591} INFO - Exporting the following env vars:
AIRFLOW_CTX_DAG_OWNER=Victor
AIRFLOW_CTX_DAG_ID=dag_etl
AIRFLOW_CTX_TASK_ID=sensor_s3_obj
AIRFLOW_CTX_EXECUTION_DATE=2023-05-16T00:00:00+00:00
AIRFLOW_CTX_TRY_NUMBER=1
AIRFLOW_CTX_DAG_RUN_ID=scheduled__2023-05-16T00:00:00+00:00
[2023-08-17 16:26:51,203] {s3.py:104} INFO - Poking for key : s3://raw/raw
[2023-08-17 16:26:51,280] {base.py:68} INFO - Using connection ID 'minio_conn' for task execution.
[2023-08-17 16:26:51,287] {base_aws.py:210} INFO - Credentials retrieved from extra_config
[2023-08-17 16:26:59,169] {s3.py:104} INFO - Poking for key : s3://raw/raw
[2023-08-17 16:27:04,182] {s3.py:104} INFO - Poking for key : s3://raw/raw
[2023-08-17 16:27:09,210] {s3.py:104} INFO - Poking for key : s3://raw/raw
[2023-08-17 16:27:14,223] {s3.py:104} INFO - Poking for key : s3://raw/raw
[2023-08-17 16:27:19,258] {s3.py:104} INFO - Poking for key : s3://raw/raw
[2023-08-17 16:27:24,273] {s3.py:104} INFO - Poking for key : s3://raw/raw
[2023-08-17 16:27:24,294] {taskinstance.py:1909} ERROR - Task failed with exception
Traceback (most recent call last):
  File "/home/airflow/.local/lib/python3.7/site-packages/airflow/sensors/base.py", line 288, in execute
    raise AirflowSensorTimeout(f"Snap. Time is OUT. DAG id: {log_dag_id}")
airflow.exceptions.AirflowSensorTimeout: Snap. Time is OUT. DAG id: dag_etl
[2023-08-17 16:27:24,413] {taskinstance.py:1420} INFO - Immediate failure requested. Marking task as FAILED. dag_id=dag_etl, task_id=sensor_s3_obj, execution_date=20230516T000000, start_date=20230817T162649, end_date=20230817T162724
[2023-08-17 16:27:24,577] {standard_task_runner.py:97} ERROR - Failed to execute job 16 for task sensor_s3_obj (Snap. Time is OUT. DAG id: dag_etl; 1309)
[2023-08-17 16:27:24,832] {local_task_job.py:156} INFO - Task exited with return code 1
[2023-08-17 16:27:25,060] {local_task_job.py:273} INFO - 0 downstream tasks scheduled from follow-on schedule check
