[2023-08-17 16:34:00,180] {taskinstance.py:1179} INFO - Dependencies all met for <TaskInstance: dag_etl.dim_customer_type manual__2023-08-17T16:33:52.832316+00:00 [queued]>
[2023-08-17 16:34:00,189] {taskinstance.py:1179} INFO - Dependencies all met for <TaskInstance: dag_etl.dim_customer_type manual__2023-08-17T16:33:52.832316+00:00 [queued]>
[2023-08-17 16:34:00,189] {taskinstance.py:1376} INFO - 
--------------------------------------------------------------------------------
[2023-08-17 16:34:00,189] {taskinstance.py:1377} INFO - Starting attempt 1 of 6
[2023-08-17 16:34:00,189] {taskinstance.py:1378} INFO - 
--------------------------------------------------------------------------------
[2023-08-17 16:34:00,201] {taskinstance.py:1397} INFO - Executing <Task(_PythonDecoratedOperator): dim_customer_type> on 2023-08-17 16:33:52.832316+00:00
[2023-08-17 16:34:00,207] {standard_task_runner.py:52} INFO - Started process 1679 to run task
[2023-08-17 16:34:00,213] {standard_task_runner.py:79} INFO - Running: ['***', 'tasks', 'run', 'dag_etl', 'dim_customer_type', 'manual__2023-08-17T16:33:52.832316+00:00', '--job-id', '28', '--raw', '--subdir', 'DAGS_FOLDER/dag_etl_taskflow.py', '--cfg-path', '/tmp/tmp9t46zwas', '--error-file', '/tmp/tmp2hac9k2c']
[2023-08-17 16:34:00,215] {standard_task_runner.py:80} INFO - Job 28: Subtask dim_customer_type
[2023-08-17 16:34:00,310] {task_command.py:371} INFO - Running <TaskInstance: dag_etl.dim_customer_type manual__2023-08-17T16:33:52.832316+00:00 [running]> on host 1ea22a5e1d7f
[2023-08-17 16:34:00,485] {taskinstance.py:1591} INFO - Exporting the following env vars:
AIRFLOW_CTX_DAG_OWNER=Victor
AIRFLOW_CTX_DAG_ID=dag_etl
AIRFLOW_CTX_TASK_ID=dim_customer_type
AIRFLOW_CTX_EXECUTION_DATE=2023-08-17T16:33:52.832316+00:00
AIRFLOW_CTX_TRY_NUMBER=1
AIRFLOW_CTX_DAG_RUN_ID=manual__2023-08-17T16:33:52.832316+00:00
[2023-08-17 16:34:00,540] {base.py:68} INFO - Using connection ID '***_conn' for task execution.
[2023-08-17 16:34:00,587] {taskinstance.py:1909} ERROR - Task failed with exception
Traceback (most recent call last):
  File "/home/airflow/.local/lib/python3.7/site-packages/sqlalchemy/engine/base.py", line 1803, in _execute_context
    cursor, statement, parameters, context
  File "/home/airflow/.local/lib/python3.7/site-packages/sqlalchemy/engine/default.py", line 719, in do_execute
    cursor.execute(statement, parameters)
psycopg2.errors.InvalidSchemaName: schema "'nds'" does not exist
LINE 2: CREATE TABLE "'nds'".dim_customer_type (
                     ^


The above exception was the direct cause of the following exception:

Traceback (most recent call last):
  File "/home/airflow/.local/lib/python3.7/site-packages/airflow/decorators/base.py", line 179, in execute
    return_value = super().execute(context)
  File "/home/airflow/.local/lib/python3.7/site-packages/airflow/operators/python.py", line 171, in execute
    return_value = self.execute_callable()
  File "/home/airflow/.local/lib/python3.7/site-packages/airflow/operators/python.py", line 189, in execute_callable
    return self.python_callable(*self.op_args, **self.op_kwargs)
  File "/opt/airflow/dags/dag_etl_taskflow.py", line 240, in dim_customer_type
    customer_type_df.to_sql('dim_customer_type', hook.get_sqlalchemy_engine(), schema=nds_layer, if_exists='replace')
  File "/home/airflow/.local/lib/python3.7/site-packages/pandas/core/generic.py", line 2882, in to_sql
    method=method,
  File "/home/airflow/.local/lib/python3.7/site-packages/pandas/io/sql.py", line 728, in to_sql
    **engine_kwargs,
  File "/home/airflow/.local/lib/python3.7/site-packages/pandas/io/sql.py", line 1758, in to_sql
    dtype=dtype,
  File "/home/airflow/.local/lib/python3.7/site-packages/pandas/io/sql.py", line 1650, in prep_table
    table.create()
  File "/home/airflow/.local/lib/python3.7/site-packages/pandas/io/sql.py", line 867, in create
    self._execute_create()
  File "/home/airflow/.local/lib/python3.7/site-packages/pandas/io/sql.py", line 853, in _execute_create
    self.table.create()
  File "/home/airflow/.local/lib/python3.7/site-packages/sqlalchemy/sql/schema.py", line 950, in create
    bind._run_ddl_visitor(ddl.SchemaGenerator, self, checkfirst=checkfirst)
  File "/home/airflow/.local/lib/python3.7/site-packages/sqlalchemy/engine/base.py", line 3110, in _run_ddl_visitor
    conn._run_ddl_visitor(visitorcallable, element, **kwargs)
  File "/home/airflow/.local/lib/python3.7/site-packages/sqlalchemy/engine/base.py", line 2113, in _run_ddl_visitor
    visitorcallable(self.dialect, self, **kwargs).traverse_single(element)
  File "/home/airflow/.local/lib/python3.7/site-packages/sqlalchemy/sql/visitors.py", line 524, in traverse_single
    return meth(obj, **kw)
  File "/home/airflow/.local/lib/python3.7/site-packages/sqlalchemy/sql/ddl.py", line 895, in visit_table
    include_foreign_key_constraints,  # noqa
  File "/home/airflow/.local/lib/python3.7/site-packages/sqlalchemy/engine/base.py", line 1289, in execute
    return meth(self, multiparams, params, _EMPTY_EXECUTION_OPTS)
  File "/home/airflow/.local/lib/python3.7/site-packages/sqlalchemy/sql/ddl.py", line 78, in _execute_on_connection
    self, multiparams, params, execution_options
  File "/home/airflow/.local/lib/python3.7/site-packages/sqlalchemy/engine/base.py", line 1387, in _execute_ddl
    compiled,
  File "/home/airflow/.local/lib/python3.7/site-packages/sqlalchemy/engine/base.py", line 1846, in _execute_context
    e, statement, parameters, cursor, context
  File "/home/airflow/.local/lib/python3.7/site-packages/sqlalchemy/engine/base.py", line 2027, in _handle_dbapi_exception
    sqlalchemy_exception, with_traceback=exc_info[2], from_=e
  File "/home/airflow/.local/lib/python3.7/site-packages/sqlalchemy/util/compat.py", line 207, in raise_
    raise exception
  File "/home/airflow/.local/lib/python3.7/site-packages/sqlalchemy/engine/base.py", line 1803, in _execute_context
    cursor, statement, parameters, context
  File "/home/airflow/.local/lib/python3.7/site-packages/sqlalchemy/engine/default.py", line 719, in do_execute
    cursor.execute(statement, parameters)
sqlalchemy.exc.ProgrammingError: (psycopg2.errors.InvalidSchemaName) schema "'nds'" does not exist
LINE 2: CREATE TABLE "'nds'".dim_customer_type (
                     ^

[SQL: 
CREATE TABLE "'nds'".dim_customer_type (
	index BIGINT, 
	customer_type TEXT
)

]
(Background on this error at: https://sqlalche.me/e/14/f405)
[2023-08-17 16:34:00,618] {taskinstance.py:1420} INFO - Marking task as UP_FOR_RETRY. dag_id=dag_etl, task_id=dim_customer_type, execution_date=20230817T163352, start_date=20230817T163400, end_date=20230817T163400
[2023-08-17 16:34:00,632] {standard_task_runner.py:97} ERROR - Failed to execute job 28 for task dim_customer_type ((psycopg2.errors.InvalidSchemaName) schema "'nds'" does not exist
LINE 2: CREATE TABLE "'nds'".dim_customer_type (
                     ^

[SQL: 
CREATE TABLE "'nds'".dim_customer_type (
	index BIGINT, 
	customer_type TEXT
)

]
(Background on this error at: https://sqlalche.me/e/14/f405); 1679)
[2023-08-17 16:34:00,668] {local_task_job.py:156} INFO - Task exited with return code 1
[2023-08-17 16:34:00,730] {local_task_job.py:273} INFO - 0 downstream tasks scheduled from follow-on schedule check
