[2023-05-02 16:49:31,569] {taskinstance.py:1159} INFO - Dependencies all met for <TaskInstance: dag_etl.dim_product_line manual__2023-05-02T16:49:00.479804+00:00 [queued]>
[2023-05-02 16:49:31,670] {taskinstance.py:1159} INFO - Dependencies all met for <TaskInstance: dag_etl.dim_product_line manual__2023-05-02T16:49:00.479804+00:00 [queued]>
[2023-05-02 16:49:31,671] {taskinstance.py:1356} INFO - 
--------------------------------------------------------------------------------
[2023-05-02 16:49:31,672] {taskinstance.py:1357} INFO - Starting attempt 1 of 6
[2023-05-02 16:49:31,673] {taskinstance.py:1358} INFO - 
--------------------------------------------------------------------------------
[2023-05-02 16:49:31,865] {taskinstance.py:1377} INFO - Executing <Task(_PythonDecoratedOperator): dim_product_line> on 2023-05-02 16:49:00.479804+00:00
[2023-05-02 16:49:31,885] {standard_task_runner.py:52} INFO - Started process 593 to run task
[2023-05-02 16:49:31,908] {standard_task_runner.py:79} INFO - Running: ['***', 'tasks', 'run', 'dag_etl', 'dim_product_line', 'manual__2023-05-02T16:49:00.479804+00:00', '--job-id', '797', '--raw', '--subdir', 'DAGS_FOLDER/dag_etl_taskflow.py', '--cfg-path', '/tmp/tmpsih08a5i', '--error-file', '/tmp/tmpr0avyp8s']
[2023-05-02 16:49:31,914] {standard_task_runner.py:80} INFO - Job 797: Subtask dim_product_line
[2023-05-02 16:49:32,912] {task_command.py:370} INFO - Running <TaskInstance: dag_etl.dim_product_line manual__2023-05-02T16:49:00.479804+00:00 [running]> on host 295d97741f96
[2023-05-02 16:49:37,634] {taskinstance.py:1571} INFO - Exporting the following env vars:
AIRFLOW_CTX_DAG_OWNER=Victor
AIRFLOW_CTX_DAG_ID=dag_etl
AIRFLOW_CTX_TASK_ID=dim_product_line
AIRFLOW_CTX_EXECUTION_DATE=2023-05-02T16:49:00.479804+00:00
AIRFLOW_CTX_TRY_NUMBER=1
AIRFLOW_CTX_DAG_RUN_ID=manual__2023-05-02T16:49:00.479804+00:00
[2023-05-02 16:49:38,843] {base.py:68} INFO - Using connection ID 'postgres_conn' for task execution.
[2023-05-02 16:49:39,197] {taskinstance.py:1889} ERROR - Task failed with exception
Traceback (most recent call last):
  File "/home/airflow/.local/lib/python3.7/site-packages/sqlalchemy/engine/base.py", line 1706, in _execute_context
    cursor, statement, parameters, context
  File "/home/airflow/.local/lib/python3.7/site-packages/sqlalchemy/engine/default.py", line 716, in do_execute
    cursor.execute(statement, parameters)
psycopg2.errors.InvalidSchemaName: schema "nds" does not exist
LINE 2: CREATE TABLE nds.dim_product_line (
                     ^


The above exception was the direct cause of the following exception:

Traceback (most recent call last):
  File "/home/airflow/.local/lib/python3.7/site-packages/airflow/decorators/base.py", line 179, in execute
    return_value = super().execute(context)
  File "/home/airflow/.local/lib/python3.7/site-packages/airflow/operators/python.py", line 171, in execute
    return_value = self.execute_callable()
  File "/home/airflow/.local/lib/python3.7/site-packages/airflow/operators/python.py", line 189, in execute_callable
    return self.python_callable(*self.op_args, **self.op_kwargs)
  File "/opt/airflow/dags/dag_etl_taskflow.py", line 258, in dim_product_line
    product_line_df.to_sql('dim_product_line', hook.get_sqlalchemy_engine(), schema=nds_layer, if_exists='replace')
  File "/home/airflow/.local/lib/python3.7/site-packages/pandas/core/generic.py", line 2882, in to_sql
    method=method,
  File "/home/airflow/.local/lib/python3.7/site-packages/pandas/io/sql.py", line 728, in to_sql
    **engine_kwargs,
  File "/home/airflow/.local/lib/python3.7/site-packages/pandas/io/sql.py", line 1758, in to_sql
    dtype=dtype,
  File "/home/airflow/.local/lib/python3.7/site-packages/pandas/io/sql.py", line 1650, in prep_table
    table.create()
  File "/home/airflow/.local/lib/python3.7/site-packages/pandas/io/sql.py", line 867, in create
    self._execute_create()
  File "/home/airflow/.local/lib/python3.7/site-packages/pandas/io/sql.py", line 853, in _execute_create
    self.table.create()
  File "/home/airflow/.local/lib/python3.7/site-packages/sqlalchemy/sql/schema.py", line 943, in create
    bind._run_ddl_visitor(ddl.SchemaGenerator, self, checkfirst=checkfirst)
  File "/home/airflow/.local/lib/python3.7/site-packages/sqlalchemy/engine/base.py", line 3008, in _run_ddl_visitor
    conn._run_ddl_visitor(visitorcallable, element, **kwargs)
  File "/home/airflow/.local/lib/python3.7/site-packages/sqlalchemy/engine/base.py", line 2016, in _run_ddl_visitor
    visitorcallable(self.dialect, self, **kwargs).traverse_single(element)
  File "/home/airflow/.local/lib/python3.7/site-packages/sqlalchemy/sql/visitors.py", line 483, in traverse_single
    return meth(obj, **kw)
  File "/home/airflow/.local/lib/python3.7/site-packages/sqlalchemy/sql/ddl.py", line 895, in visit_table
    include_foreign_key_constraints,  # noqa
  File "/home/airflow/.local/lib/python3.7/site-packages/sqlalchemy/engine/base.py", line 1200, in execute
    return meth(self, multiparams, params, _EMPTY_EXECUTION_OPTS)
  File "/home/airflow/.local/lib/python3.7/site-packages/sqlalchemy/sql/ddl.py", line 78, in _execute_on_connection
    self, multiparams, params, execution_options
  File "/home/airflow/.local/lib/python3.7/site-packages/sqlalchemy/engine/base.py", line 1296, in _execute_ddl
    compiled,
  File "/home/airflow/.local/lib/python3.7/site-packages/sqlalchemy/engine/base.py", line 1749, in _execute_context
    e, statement, parameters, cursor, context
  File "/home/airflow/.local/lib/python3.7/site-packages/sqlalchemy/engine/base.py", line 1930, in _handle_dbapi_exception
    sqlalchemy_exception, with_traceback=exc_info[2], from_=e
  File "/home/airflow/.local/lib/python3.7/site-packages/sqlalchemy/util/compat.py", line 211, in raise_
    raise exception
  File "/home/airflow/.local/lib/python3.7/site-packages/sqlalchemy/engine/base.py", line 1706, in _execute_context
    cursor, statement, parameters, context
  File "/home/airflow/.local/lib/python3.7/site-packages/sqlalchemy/engine/default.py", line 716, in do_execute
    cursor.execute(statement, parameters)
sqlalchemy.exc.ProgrammingError: (psycopg2.errors.InvalidSchemaName) schema "nds" does not exist
LINE 2: CREATE TABLE nds.dim_product_line (
                     ^

[SQL: 
CREATE TABLE nds.dim_product_line (
	index BIGINT, 
	product_line TEXT
)

]
(Background on this error at: http://sqlalche.me/e/14/f405)
[2023-05-02 16:49:39,853] {taskinstance.py:1400} INFO - Marking task as UP_FOR_RETRY. dag_id=dag_etl, task_id=dim_product_line, execution_date=20230502T164900, start_date=20230502T164931, end_date=20230502T164939
[2023-05-02 16:49:41,436] {standard_task_runner.py:97} ERROR - Failed to execute job 797 for task dim_product_line ((psycopg2.errors.InvalidSchemaName) schema "nds" does not exist
LINE 2: CREATE TABLE nds.dim_product_line (
                     ^

[SQL: 
CREATE TABLE nds.dim_product_line (
	index BIGINT, 
	product_line TEXT
)

]
(Background on this error at: http://sqlalche.me/e/14/f405); 593)
[2023-05-02 16:49:41,602] {local_task_job.py:156} INFO - Task exited with return code 1
[2023-05-02 16:49:43,215] {local_task_job.py:273} INFO - 0 downstream tasks scheduled from follow-on schedule check
