[2023-04-30 11:59:49,368] {taskinstance.py:1159} INFO - Dependencies all met for <TaskInstance: dag_etl.dim_date manual__2023-04-30T11:58:50.689561+00:00 [queued]>
[2023-04-30 11:59:49,959] {taskinstance.py:1159} INFO - Dependencies all met for <TaskInstance: dag_etl.dim_date manual__2023-04-30T11:58:50.689561+00:00 [queued]>
[2023-04-30 11:59:49,988] {taskinstance.py:1356} INFO - 
--------------------------------------------------------------------------------
[2023-04-30 11:59:50,003] {taskinstance.py:1357} INFO - Starting attempt 1 of 6
[2023-04-30 11:59:50,011] {taskinstance.py:1358} INFO - 
--------------------------------------------------------------------------------
[2023-04-30 11:59:51,021] {taskinstance.py:1377} INFO - Executing <Task(_PythonDecoratedOperator): dim_date> on 2023-04-30 11:58:50.689561+00:00
[2023-04-30 11:59:51,123] {standard_task_runner.py:52} INFO - Started process 605 to run task
[2023-04-30 11:59:51,228] {standard_task_runner.py:79} INFO - Running: ['***', 'tasks', 'run', 'dag_etl', 'dim_date', 'manual__2023-04-30T11:58:50.689561+00:00', '--job-id', '248', '--raw', '--subdir', 'DAGS_FOLDER/dag_etl_taskflow.py', '--cfg-path', '/tmp/tmp4qk7w_ea', '--error-file', '/tmp/tmpzz9mijh3']
[2023-04-30 11:59:51,312] {standard_task_runner.py:80} INFO - Job 248: Subtask dim_date
[2023-04-30 11:59:53,115] {task_command.py:370} INFO - Running <TaskInstance: dag_etl.dim_date manual__2023-04-30T11:58:50.689561+00:00 [running]> on host 295d97741f96
[2023-04-30 11:59:59,012] {taskinstance.py:1571} INFO - Exporting the following env vars:
AIRFLOW_CTX_DAG_OWNER=Victor
AIRFLOW_CTX_DAG_ID=dag_etl
AIRFLOW_CTX_TASK_ID=dim_date
AIRFLOW_CTX_EXECUTION_DATE=2023-04-30T11:58:50.689561+00:00
AIRFLOW_CTX_TRY_NUMBER=1
AIRFLOW_CTX_DAG_RUN_ID=manual__2023-04-30T11:58:50.689561+00:00
[2023-04-30 12:00:43,305] {base.py:68} INFO - Using connection ID 'postgres_conn' for task execution.
[2023-04-30 12:00:46,004] {taskinstance.py:1889} ERROR - Task failed with exception
Traceback (most recent call last):
  File "/home/airflow/.local/lib/python3.7/site-packages/sqlalchemy/engine/base.py", line 1706, in _execute_context
    cursor, statement, parameters, context
  File "/home/airflow/.local/lib/python3.7/site-packages/sqlalchemy/engine/default.py", line 716, in do_execute
    cursor.execute(statement, parameters)
psycopg2.errors.DependentObjectsStillExist: cannot drop table nds.dim_date because other objects depend on it
DETAIL:  view dns_sales depends on table nds.dim_date
HINT:  Use DROP ... CASCADE to drop the dependent objects too.


The above exception was the direct cause of the following exception:

Traceback (most recent call last):
  File "/home/airflow/.local/lib/python3.7/site-packages/airflow/decorators/base.py", line 179, in execute
    return_value = super().execute(context)
  File "/home/airflow/.local/lib/python3.7/site-packages/airflow/operators/python.py", line 171, in execute
    return_value = self.execute_callable()
  File "/home/airflow/.local/lib/python3.7/site-packages/airflow/operators/python.py", line 189, in execute_callable
    return self.python_callable(*self.op_args, **self.op_kwargs)
  File "/opt/airflow/dags/dag_etl_taskflow.py", line 265, in dim_date
    'week_start': sqlalchemy.types.Date()})
  File "/home/airflow/.local/lib/python3.7/site-packages/pandas/core/generic.py", line 2882, in to_sql
    method=method,
  File "/home/airflow/.local/lib/python3.7/site-packages/pandas/io/sql.py", line 728, in to_sql
    **engine_kwargs,
  File "/home/airflow/.local/lib/python3.7/site-packages/pandas/io/sql.py", line 1758, in to_sql
    dtype=dtype,
  File "/home/airflow/.local/lib/python3.7/site-packages/pandas/io/sql.py", line 1650, in prep_table
    table.create()
  File "/home/airflow/.local/lib/python3.7/site-packages/pandas/io/sql.py", line 860, in create
    self.pd_sql.drop_table(self.name, self.schema)
  File "/home/airflow/.local/lib/python3.7/site-packages/pandas/io/sql.py", line 1810, in drop_table
    self.get_table(table_name, schema).drop()
  File "/home/airflow/.local/lib/python3.7/site-packages/sqlalchemy/sql/schema.py", line 960, in drop
    bind._run_ddl_visitor(ddl.SchemaDropper, self, checkfirst=checkfirst)
  File "/home/airflow/.local/lib/python3.7/site-packages/sqlalchemy/engine/base.py", line 3008, in _run_ddl_visitor
    conn._run_ddl_visitor(visitorcallable, element, **kwargs)
  File "/home/airflow/.local/lib/python3.7/site-packages/sqlalchemy/engine/base.py", line 2016, in _run_ddl_visitor
    visitorcallable(self.dialect, self, **kwargs).traverse_single(element)
  File "/home/airflow/.local/lib/python3.7/site-packages/sqlalchemy/sql/visitors.py", line 483, in traverse_single
    return meth(obj, **kw)
  File "/home/airflow/.local/lib/python3.7/site-packages/sqlalchemy/sql/ddl.py", line 1097, in visit_table
    self.connection.execute(DropTable(table))
  File "/home/airflow/.local/lib/python3.7/site-packages/sqlalchemy/engine/base.py", line 1200, in execute
    return meth(self, multiparams, params, _EMPTY_EXECUTION_OPTS)
  File "/home/airflow/.local/lib/python3.7/site-packages/sqlalchemy/sql/ddl.py", line 78, in _execute_on_connection
    self, multiparams, params, execution_options
  File "/home/airflow/.local/lib/python3.7/site-packages/sqlalchemy/engine/base.py", line 1296, in _execute_ddl
    compiled,
  File "/home/airflow/.local/lib/python3.7/site-packages/sqlalchemy/engine/base.py", line 1749, in _execute_context
    e, statement, parameters, cursor, context
  File "/home/airflow/.local/lib/python3.7/site-packages/sqlalchemy/engine/base.py", line 1930, in _handle_dbapi_exception
    sqlalchemy_exception, with_traceback=exc_info[2], from_=e
  File "/home/airflow/.local/lib/python3.7/site-packages/sqlalchemy/util/compat.py", line 211, in raise_
    raise exception
  File "/home/airflow/.local/lib/python3.7/site-packages/sqlalchemy/engine/base.py", line 1706, in _execute_context
    cursor, statement, parameters, context
  File "/home/airflow/.local/lib/python3.7/site-packages/sqlalchemy/engine/default.py", line 716, in do_execute
    cursor.execute(statement, parameters)
sqlalchemy.exc.InternalError: (psycopg2.errors.DependentObjectsStillExist) cannot drop table nds.dim_date because other objects depend on it
DETAIL:  view dns_sales depends on table nds.dim_date
HINT:  Use DROP ... CASCADE to drop the dependent objects too.

[SQL: 
DROP TABLE nds.dim_date]
(Background on this error at: http://sqlalche.me/e/14/2j85)
[2023-04-30 12:00:48,305] {taskinstance.py:1400} INFO - Marking task as UP_FOR_RETRY. dag_id=dag_etl, task_id=dim_date, execution_date=20230430T115850, start_date=20230430T115949, end_date=20230430T120048
[2023-04-30 12:01:01,021] {standard_task_runner.py:97} ERROR - Failed to execute job 248 for task dim_date ((psycopg2.errors.DependentObjectsStillExist) cannot drop table nds.dim_date because other objects depend on it
DETAIL:  view dns_sales depends on table nds.dim_date
HINT:  Use DROP ... CASCADE to drop the dependent objects too.

[SQL: 
DROP TABLE nds.dim_date]
(Background on this error at: http://sqlalche.me/e/14/2j85); 605)
[2023-04-30 12:01:01,678] {local_task_job.py:156} INFO - Task exited with return code 1
[2023-04-30 12:01:12,359] {local_task_job.py:273} INFO - 0 downstream tasks scheduled from follow-on schedule check
